Workbook

Sheet Lisez-moi
A1: Cartographie du sport associatif et du sport féminin en Val d'Oise
A2: Base consolidée construite à partir des fichiers de la Direction des Sports. Version du 21/09/2026.
A4: Onglet | B4: Contenu
A5: Communes | B5: 183 communes du Val d'Oise. Volumes 2025 (associations civiles, adhérent·es F/H, bénévoles F, salariées F), scolaires, subventions, équipements, manifestations, sections sportives, séries 2019-2025. Les ratios sont des formules.
A6: Cantons | B6: 18 cantons regroupés (Argenteuil 1-2-3 et Cergy 1-2 fusionnés, car ils découpent une même commune). Sommes par SUMIFS sur l'onglet Communes.
A7: EPCI | B7: 12 intercommunalités (rattachement au code officiel géographique). Sommes par SUMIFS sur l'onglet Communes.
A8: Associations_2025 | B8: Liste des 553 associations civiles 2025 avec commune, canton, EPCI, adhérent·es F/H, part F et profil de mixité.
A9: Evolution | B9: Totaux départementaux 2019-2025 : nombre d'associations civiles et volume de licencié·es / adhérent·es.
A10: Comites | B10: Comités départementaux : licencié·es et féminines par saison (2022/23 à 2025/26), actions « pratique féminine ».
A11: Gouvernance | B11: Enquête 2021 (pratiquantes, bénévoles, éducatrices, arbitres, présidentes) et répartition F/H des élu·es et directeur·rices des sports.
A12: Sections_sportives | B12: Sections sportives scolaires 2026-2027 du Val d'Oise (extrait du PDF académique).
A13: Installations | B13: Liste des 1 543 lieux de pratique, avec code commune.
A15: Définitions et limites
A16: Champ | B16: Les fichiers « associations civiles (01) et scolaires (02) » portent sur les associations aidées par le Département. Ce n'est pas un recensement de tous les clubs. Une commune « sans association » peut avoir des clubs non aidés.
A17: Part F 2025 | B17: Adhérentes féminines / (adhérentes + adhérents masculins), déclaré par les associations en 2025. Même calcul pour 2024.
A18: Libellés trompeurs | B18: Dans les fichiers 2023-2025, plusieurs colonnes libellées « F » contiennent en fait des totaux F+H. Ex. 2025 : « Licencié F » = adhérents F+H dans 99 % des cas ; « Moins 18 F » + « Plus 18 F » = total F+H dans 95 % des cas. Ces colonnes ne sont pas utilisées comme données féminines. Idem pour « licencié Feminine » en 2023, traité comme un total.
A19: Rupture de série | B19: Jusqu'en 2023 le volume est un nombre de licencié·es ; en 2024-2025 c'est un nombre d'adhérent·es (F+H). La hausse 2023-2024 reflète en partie ce changement de mesure.
A20: Scolaires 2025 | B20: La colonne s'intitule « Nombre Licencié F ». Le libellé n'est pas vérifiable ; le chiffre est probablement un total. À confirmer avec la Direction des Sports.
A21: Cantons | B21: Canton connu pour 108 communes (liste des subventions 2025). Pour les 75 autres, canton imputé à partir de la commune voisine la plus proche (colonne « canton_source »). À vérifier avec la liste officielle INSEE.
A22: Population | B22: Population municipale du code officiel géographique (paquet etalab « découpage administratif », mars 2026).
A23: Taux pour 1 000 hab. | B23: Les adhérent·es sont comptés dans la commune du siège de l'association, pas dans leur commune de résidence. Les taux par habitant indiquent une offre locale, pas une pratique des habitantes.
A24: Effectifs faibles | B24: Une part F calculée sur moins de 100 adhérent·es est fragile (colonne « fiabilite_part_F »).
A25: Installations | B25: Chaque ligne est un lieu. La colonne source « installation Nombre » n'est pas documentée ; elle est reprise sans être interprétée.
A26: Hors département | B26: 2 associations civiles 2025 et 2 associations subventionnées ont leur siège hors Val d'Oise (Conflans-Sainte-Honorine, Sacy-le-Grand, Belle-Église). Elles sont exclues des agrégats communaux.
A28: Ajouts 22/09/2026
A29: Disciplines_5_saisons | B29: Part des femmes par discipline : 2020/21 (enquête) puis 2022/23 à 2025/26 (comités). Total calculé sur les disciplines présentes les 5 saisons.
A30: Territoires_2019_2025 | B30: Nombre d'associations aidées, volume de licencié·es / adhérent·es et panel d'associations présentes les 7 années, par canton et intercommunalité.

Sheet Communes
A1: Indicateurs par commune
A2: Colonnes grises = données sources agrégées ; colonnes de droite = ratios calculés par formule. Voir Lisez-moi pour les définitions.
A4: Code INSEE | B4: Commune | C4: Canton | D4: Source du canton | E4: EPCI | F4: Grille de densité INSEE | G4: Population | H4: Asso. civiles 2025 | I4: Adhérentes F 2025 | J4: Adhérents H 2025 | K4: Bénévoles F 2025 | L4: Salariées F 2025 | M4: Asso. <20 % F (2025) | N4: Asso. ≥60 % F (2025) | O4: Asso. civiles 2024 | P4: Adhérentes F 2024 | Q4: Adhérents H 2024 | R4: Asso. scolaires 2025 | S4: Licencié·es scolaires 2025 (libellé F) | T4: Sections scolaires 2025 | U4: Asso. civiles subventionnées 2025 | V4: Asso. scolaires subventionnées 2025 | W4: Lieux de pratique | X4: dont établissements scolaires | Y4: dont piscines | Z4: Manifestations 2023 | AA4: Manifestations 2024 | AB4: Manifestations 2025 | AC4: Sections sportives scolaires 2026-27 | AD4: dont sections féminines | AE4: Asso. civiles 2019 | AF4: Asso. civiles 2020 | AG4: Asso. civiles 2021 | AH4: Asso. civiles 2022 | AI4: Asso. civiles 2023 | AJ4: Licencié·es / adhérent·es 2019 | AK4: Licencié·es / adhérent·es 2020 | AL4: Licencié·es / adhérent·es 2021 | AM4: Licencié·es / adhérent·es 2022 | AN4: Licencié·es / adhérent·es 2023 | AO4: Licencié·es / adhérent·es 2024 | AP4: Licencié·es / adhérent·es 2025 | AQ4: Adhérent·es total 2025 | AR4: Part F 2025 | AS4: Part F 2024 | AT4: Évolution part F (points) | AU4: Adhérentes F pour 1 000 hab. | AV4: Asso. civiles pour 10 000 hab. | AW4: Lieux pour 10 000 hab. | AX4: Bénévoles F pour 100 adhérentes | AY4: Fiabilité part F
A5: 95002 | B5: Ableiges | C5: Pontoise | D5: liste subventions 2025 | E5: CC Vexin Centre | F5: Rural à habitat dispersé | G5: 1108 | H5: 1 | I5: 38 | J5: 185 | K5: 7 | L5: 0 | M5: 1 | N5: 0 | O5: 1 | P5: 43 | Q5: 141 | R5: 0 | S5: 0 | T5: 0 | U5: 1 | V5: 0 | W5: 5 | X5: 2 | Y5: 0 | Z5: 0 | AA5: 0 | AB5: 0 | AC5: 0 | AD5: 0 | AE5: 2 | AF5: 2 | AG5: 2 | AH5: 2 | AI5: 2 | AJ5: 453 | AK5: 434 | AL5: 316 | AM5: 156 | AN5: 198 | AO5: 184 | AP5: 223 | AQ5: =I5+J5 -> 223 | AR5: =IF(AQ5>0,I5/AQ5,"") -> 0.17040359 | AS5: =IF((P5+Q5)>0,P5/(P5+Q5),"") -> 0.23369565 | AT5: =IF(AND(ISNUMBER(AR5),ISNUMBER(AS5)),(AR5-AS5)*100,"") -> -6.3292065 | AU5: =IF(G5>0,I5/G5*1000,"") -> 34.296029 | AV5: =IF(G5>0,H5/G5*10000,"") -> 9.0252708 | AW5: =IF(G5>0,W5/G5*10000,"") -> 45.126354 | AX5: =IF(I5>0,K5/I5*100,"") -> 18.421053 | AY5: =IF(AQ5>=100,"ok",IF(AQ5>0,"effectif faible (<100)","aucune association")) -> ok
A6: 95008 | B6: Aincourt | C6: Vauréal | D6: imputé (commune voisine la plus proche) | E6: CC du Vexin-Val de Seine | F6: Rural à habitat dispersé | G6: 854 | H6: 0 | I6: 0 | J6: 0 | K6: 0 | L6: 0 | M6: 0 | N6: 0 | O6: 0 | P6: 0 | Q6: 0 | R6: 0 | S6: 0 | T6: 0 | U6: 0 | V6: 0 | W6: 3 | X6: 1 | Y6: 0 | Z6: 0 | AA6: 0 | AB6: 0 | AC6: 0 | AD6: 0 | AE6: 0 | AF6: 0 | AG6: 0 | AH6: 0 | AI6: 0 | AJ6: 0 | AK6: 0 | AL6: 0 | AM6: 0 | AN6: 0 | AO6: 0 | AP6: 0 | AQ6: =I6+J6 -> 0 | AR6: =IF(AQ6>0,I6/AQ6,"") | AS6: =IF((P6+Q6)>0,P6/(P6+Q6),"") | AT6: =IF(AND(ISNUMBER(AR6),ISNUMBER(AS6)),(AR6-AS6)*100,"") | AU6: =IF(G6>0,I6/G6*1000,"") -> 0 | AV6: =IF(G6>0,H6/G6*10000,"") -> 0 | AW6: =IF(G6>0,W6/G6*10000,"") -> 35.128806 | AX6: =IF(I6>0,K6/I6*100,"") | AY6: =IF(AQ6>=100,"ok",IF(AQ6>0,"effectif faible (<100)","aucune association")) -> aucune association
A7: 95011 | B7: Ambleville | C7: Vauréal | D7: imputé (commune voisine la plus proche) | E7: CC du Vexin-Val de Seine | G7: 388 | H7: 0 | I7: 0 | J7: 0 | K7: 0 | L7: 0 | M7: 0 | N7: 0 | O7: 0 | P7: 0 | Q7: 0 | R7: 0 | S7: 0 | T7: 0 | U7: 0 | V7: 0 | W7: 0 | X7: 0 | Y7: 0 | Z7: 0 | AA7: 0 | AB7: 0 | AC7: 0 | AD7: 0 | AE7: 0 | AF7: 0 | AG7: 0 | AH7: 0 | AI7: 0 | AJ7: 0 | AK7: 0 | AL7: 0 | AM7: 0 | AN7: 0 | AO7: 0 | AP7: 0 | AQ7: =I7+J7 -> 0 | AR7: =IF(AQ7>0,I7/AQ7,"") | AS7: =IF((P7+Q7)>0,P7/(P7+Q7),"") | AT7: =IF(AND(ISNUMBER(AR7),ISNUMBER(AS7)),(AR7-AS7)*100,"") | AU7: =IF(G7>0,I7/G7*1000,"") -> 0 | AV7: =IF(G7>0,H7/G7*10000,"") -> 0 | AW7: =IF(G7>0,W7/G7*10000,"") -> 0 | AX7: =IF(I7>0,K7/I7*100,"") | AY7: =IF(AQ7>=100,"ok",IF(AQ7>0,"effectif faible (<100)","aucune association")) -> aucune association
A8: 95012 | B8: Amenucourt | C8: Vauréal | D8: imputé (commune voisine la plus proche) | E8: CC du Vexin-Val de Seine | F8: Rural à habitat dispersé | G8: 212 | H8: 0 | I8: 0 | J8: 0 | K8: 0 | L8: 0 | M8: 0 | N8: 0 | O8: 0 | P8: 0 | Q8: 0 | R8: 0 | S8: 0 | T8: 0 | U8: 0 | V8: 0 | W8: 1 | X8: 0 | Y8: 0 | Z8: 0 | AA8: 0 | AB8: 0 | AC8: 0 | AD8: 0 | AE8: 0 | AF8: 0 | AG8: 0 | AH8: 0 | AI8: 0 | AJ8: 0 | AK8: 0 | AL8: 0 | AM8: 0 | AN8: 0 | AO8: 0 | AP8: 0 | AQ8: =I8+J8 -> 0 | AR8: =IF(AQ8>0,I8/AQ8,"") | AS8: =IF((P8+Q8)>0,P8/(P8+Q8),"") | AT8: =IF(AND(ISNUMBER(AR8),ISNUMBER(AS8)),(AR8-AS8)*100,"") | AU8: =IF(G8>0,I8/G8*1000,"") -> 0 | AV8: =IF(G8>0,H8/G8*10000,"") -> 0 | AW8: =IF(G8>0,W8/G8*10000,"") -> 47.169811 | AX8: =IF(I8>0,K8/I8*100,"") | AY8: =IF(AQ8>=100,"ok",IF(AQ8>0,"effectif faible (<100)","aucune association")) -> aucune association
A9: 95014 | B9: Andilly | C9: Montmorency | D9: imputé (commune voisine la plus proche) | E9: CA Plaine Vallée | F9: Grands centres urbains | G9: 2742 | H9: 0 | I9: 0 | J9: 0 | K9: 0 | L9: 0 | M9: 0 | N9: 0 | O9: 0 | P9: 0 | Q9: 0 | R9: 0 | S9: 0 | T9: 0 | U9: 0 | V9: 0 | W9: 6 | X9: 1 | Y9: 0 | Z9: 0 | AA9: 0 | AB9: 0 | AC9: 0 | AD9: 0 | AE9: 0 | AF9: 0 | AG9: 0 | AH9: 0 | AI9: 0 | AJ9: 0 | AK9: 0 | AL9: 0 | AM9: 0 | AN9: 0 | AO9: 0 | AP9: 0 | AQ9: =I9+J9 -> 0 | AR9: =IF(AQ9>0,I9/AQ9,"") | AS9: =IF((P9+Q9)>0,P9/(P9+Q9),"") | AT9: =IF(AND(ISNUMBER(AR9),ISNUMBER(AS9)),(AR9-AS9)*100,"") | AU9: =IF(G9>0,I9/G9*1000,"") -> 0 | AV9: =IF(G9>0,H9/G9*10000,"") -> 0 | AW9: =IF(G9>0,W9/G9*10000,"") -> 21.881838 | AX9: =IF(I9>0,K9/I9*100,"") | AY9: =IF(AQ9>=100,"ok",IF(AQ9>0,"effectif faible (<100)","aucune association")) -> aucune association
A10: 95018 | B10: Argenteuil | C10: Argenteuil (1-2-3) | D10: liste subventions 2025 | E10: Métropole du Grand Paris | F10: Grands centres urbains | G10: 106130 | H10: 24 | I10: 3364 | J10: 5334 | K10: 679 | L10: 68 | M10: 6 | N10: 3 | O10: 22 | P10: 3398 | Q10: 3688 | R10: 6 | S10: 683 | T10: 26 | U10: 24 | V10: 6 | W10: 68 | X10: 14 | Y10: 1 | Z10: 2 | AA10: 2 | AB10: 0 | AC10: 4 | AD10: 0 | AE10: 21 | AF10: 26 | AG10: 25 | AH10: 25 | AI10: 23 | AJ10: 7854 | AK10: 8955 | AL10: 8268 | AM10: 6751 | AN10: 6733 | AO10: 7086 | AP10: 8698 | AQ10: =I10+J10 -> 8698 | AR10: =IF(AQ10>0,I10/AQ10,"") -> 0.38675558 | AS10: =IF((P10+Q10)>0,P10/(P10+Q10),"") -> 0.47953712 | AT10: =IF(AND(ISNUMBER(AR10),ISNUMBER(AS10)),(AR10-AS10)*100,"") -> -9.2781539 | AU10: =IF(G10>0,I10/G10*1000,"") -> 31.696975 | AV10: =IF(G10>0,H10/G10*10000,"") -> 2.2613776 | AW10: =IF(G10>0,W10/G10*10000,"") -> 6.4072364 | AX10: =IF(I10>0,K10/I10*100,"") -> 20.184304 | AY10: =IF(AQ10>=100,"ok",IF(AQ10>0,"effectif faible (<100)","aucune association")) -> ok
A11: 95019 | B11: Arnouville | C11: Garges-lès-Gonesse | D11: liste subventions 2025 | E11: CA Roissy Pays de France | F11: Grands centres urbains | G11: 15023 | H11: 3 | I11: 137 | J11: 211 | K11: 77 | L11: 3 | M11: 0 | N11: 1 | O11: 3 | P11: 166 | Q11: 116 | R11: 1 | S11: 110 | T11: 3 | U11: 3 | V11: 1 | W11: 17 | X11: 10 | Y11: 0 | Z11: 0 | AA11: 0 | AB11: 0 | AC11: 0 | AD11: 0 | AE11: 5 | AF11: 5 | AG11: 4 | AH11: 3 | AI11: 3 | AJ11: 331 | AK11: 403 | AL11: 407 | AM11: 194 | AN11: 208 | AO11: 282 | AP11: 348 | AQ11: =I11+J11 -> 348 | AR11: =IF(AQ11>0,I11/AQ11,"") -> 0.39367816 | AS11: =IF((P11+Q11)>0,P11/(P11+Q11),"") -> 0.58865248 | AT11: =IF(AND(ISNUMBER(AR11),ISNUMBER(AS11)),(AR11-AS11)*100,"") -> -19.497432 | AU11: =IF(G11>0,I11/G11*1000,"") -> 9.1193503 | AV11: =IF(G11>0,H11/G11*10000,"") -> 1.996938 | AW11: =IF(G11>0,W11/G11*10000,"") -> 11.315982 | AX11: =IF(I11>0,K11/I11*100,"") -> 56.20438 | AY11: =IF(AQ11>=100,"ok",IF(AQ11>0,"effectif faible (<100)","aucune association")) -> ok
A12: 95023 | B12: Arronville | C12: Pontoise | D12: liste subventions 2025 | E12: CC Sausseron Impressionnistes | F12: Rural à habitat dispersé | G12: 618 | H12: 1 | I12: 5 | J12: 9 | K12: 0 | L12: 0 | M12: 0 | N12: 0 | O12: 1 | P12: 6 | Q12: 11 | R12: 0 | S12: 0 | T12: 0 | U12: 1 | V12: 0 | W12: 1 | X12: 1 | Y12: 0 | Z12: 0 | AA12: 0 | AB12: 0 | AC12: 0 | AD12: 0 | AE12: 1 | AF12: 1 | AG12: 1 | AH12: 1 | AI12: 1 | AJ12: 11 | AK12: 14 | AL12: 15 | AM12: 13 | AN12: 15 | AO12: 17 | AP12: 14 | AQ12: =I12+J12 -> 14 | AR12: =IF(AQ12>0,I12/AQ12,"") -> 0.35714286 | AS12: =IF((P12+Q12)>0,P12/(P12+Q12),"") -> 0.35294118 | AT12: =IF(AND(ISNUMBER(AR12),ISNUMBER(AS12)),(AR12-AS12)*100,"") -> 0.42016807 | AU12: =IF(G12>0,I12/G12*1000,"") -> 8.0906149 | AV12: =IF(G12>0,H12/G12*10000,"") -> 16.18123 | AW12: =IF(G12>0,W12/G12*10000,"") -> 16.18123 | AX12: =IF(I12>0,K12/I12*100,"") -> 0 | AY12: =IF(AQ12>=100,"ok",IF(AQ12>0,"effectif faible (<100)","aucune association")) -> effectif faible (<100)
A13: 95024 | B13: Arthies | C13: Vauréal | D13: liste subventions 2025 | E13: CC du Vexin-Val de Seine | F13: Rural à habitat dispersé | G13: 265 | H13: 1 | I13: 30 | J13: 23 | K13: 8 | L13: 1 | M13: 0 | N13: 0 | O13: 1 | P13: 20 | Q13: 22 | R13: 0 | S13: 0 | T13: 0 | U13: 1 | V13: 0 | W13: 4 | X13: 0 | Y13: 0 | Z13: 0 | AA13: 0 | AB13: 0 | AC13: 0 | AD13: 0 | AE13: 1 | AF13: 1 | AG13: 1 | AH13: 1 | AI13: 1 | AJ13: 72 | AK13: 60 | AL13: 70 | AM13: 66 | AN13: 61 | AO13: 42 | AP13: 53 | AQ13: =I13+J13 -> 53 | AR13: =IF(AQ13>0,I13/AQ13,"") -> 0.56603774 | AS13: =IF((P13+Q13)>0,P13/(P13+Q13),"") -> 0.47619048 | AT13: =IF(AND(ISNUMBER(AR13),ISNUMBER(AS13)),(AR13-AS13)*100,"") -> 8.984726 | AU13: =IF(G13>0,I13/G13*1000,"") -> 113.20755 | AV13: =IF(G13>0,H13/G13*10000,"") -> 37.735849 | AW13: =IF(G13>0,W13/G13*10000,"") -> 150.9434 | AX13: =IF(I13>0,K13/I13*100,"") -> 26.666667 | AY13: =IF(AQ13>=100,"ok",IF(AQ13>0,"effectif faible (<100)","aucune association")) -> effectif faible (<100)
A14: 95026 | B14: Asnières-sur-Oise | C14: Fosses | D14: imputé (commune voisine la plus proche) | E14: CC Carnelle Pays-de-France | F14: Ceintures urbaines | G14: 3127 | H14: 0 | I14: 0 | J14: 0 | K14: 0 | L14: 0 | M14: 0 | N14: 0 | O14: 1 | P14: 184 | Q14: 15 | R14: 0 | S14: 0 | T14: 0 | U14: 0 | V14: 0 | W14: 2 | X14: 0 | Y14: 0 | Z14: 0 | AA14: 0 | AB14: 0 | AC14: 0 | AD14: 0 | AE14: 1 | AF14: 1 | AG14: 1 | AH14: 1 | AI14: 1 | AJ14: 0 | AK14: 0 | AL14: 0 | AM14: 0 | AN14: 0 | AO14: 199 | AP14: 0 | AQ14: =I14+J14 -> 0 | AR14: =IF(AQ14>0,I14/AQ14,"") | AS14: =IF((P14+Q14)>0,P14/(P14+Q14),"") -> 0.92462312 | AT14: =IF(AND(ISNUMBER(AR14),ISNUMBER(AS14)),(AR14-AS14)*100,"") | AU14: =IF(G14>0,I14/G14*1000,"") -> 0 | AV14: =IF(G14>0,H14/G14*10000,"") -> 0 | AW14: =IF(G14>0,W14/G14*10000,"") -> 6.3959066 | AX14: =IF(I14>0,K14/I14*100,"") | AY14: =IF(AQ14>=100,"ok",IF(AQ14>0,"effectif faible (<100)","aucune association")) -> aucune association
A15: 95028 | B15: Attainville | C15: Fosses | D15: liste subventions 2025 | E15: CA Plaine Vallée | F15: Ceintures urbaines | G15: 1904 | H15: 3 | I15: 284 | J15: 391 | K15: 43 | L15: 7 | M15: 1 | N15: 1 | O15: 3 | P15: 301 | Q15: 329 | R15: 0 | S15: 0 | T15: 0 | U15: 3 | V15: 0 | W15: 4 | X15: 0 | Y15: 0 | Z15: 0 | AA15: 0 | AB15: 0 | AC15: 0 | AD15: 0 | AE15: 1 | AF15: 2 | AG15: 3 | AH15: 2 | AI15: 3 | AJ15: 140 | AK15: 245 | AL15: 288 | AM15: 137 | AN15: 360 | AO15: 630 | AP15: 675 | AQ15: =I15+J15 -> 675 | AR15: =IF(AQ15>0,I15/AQ15,"") -> 0.42074074 | AS15: =IF((P15+Q15)>0,P15/(P15+Q15),"") -> 0.47777778 | AT15: =IF(AND(ISNUMBER(AR15),ISNUMBER(AS15)),(AR15-AS15)*100,"") -> -5.7037037 | AU15: =IF(G15>0,I15/G15*1000,"") -> 149.15966 | AV15: =IF(G15>0,H15/G15*10000,"") -> 15.756303 | AW15: =IF(G15>0,W15/G15*10000,"") -> 21.008403 | AX15: =IF(I15>0,K15/I15*100,"") -> 15.140845 | AY15: =IF(AQ15>=100,"ok",IF(AQ15>0,"effectif faible (<100)","aucune association")) -> ok
A16: 95039 | B16: Auvers-sur-Oise | C16: Saint-Ouen-l'Aumône | D16: liste subventions 2025 | E16: CC Sausseron Impressionnistes | F16: Grands centres urbains | G16: 6863 | H16: 6 | I16: 462 | J16: 817 | K16: 112 | L16: 5 | M16: 1 | N16: 3 | O16: 7 | P16: 468 | Q16: 837 | R16: 2 | S16: 443 | T16: 7 | U16: 7 | V16: 2 | W16: 12 | X16: 2 | Y16: 0 | Z16: 0 | AA16: 0 | AB16: 0 | AC16: 1 | AD16: 0 | AE16: 6 | AF16: 7 | AG16: 8 | AH16: 7 | AI16: 7 | AJ16: 1849 | AK16: 1648 | AL16: 1245 | AM16: 1268 | AN16: 1116 | AO16: 1305 | AP16: 1279 | AQ16: =I16+J16 -> 1279 | AR16: =IF(AQ16>0,I16/AQ16,"") -> 0.3612197 | AS16: =IF((P16+Q16)>0,P16/(P16+Q16),"") -> 0.35862069 | AT16: =IF(AND(ISNUMBER(AR16),ISNUMBER(AS16)),(AR16-AS16)*100,"") -> 0.25990132 | AU16: =IF(G16>0,I16/G16*1000,"") -> 67.3175 | AV16: =IF(G16>0,H16/G16*10000,"") -> 8.7425324 | AW16: =IF(G16>0,W16/G16*10000,"") -> 17.485065 | AX16: =IF(I16>0,K16/I16*100,"") -> 24.242424 | AY16: =IF(AQ16>=100,"ok",IF(AQ16>0,"effectif faible (<100)","aucune association")) -> ok
A17: 95040 | B17: Avernes | C17: Vauréal | D17: liste subventions 2025 | E17: CC Vexin Centre | F17: Bourgs ruraux | G17: 871 | H17: 1 | I17: 2 | J17: 45 | K17: 6 | L17: 0 | M17: 1 | N17: 0 | O17: 1 | P17: 2 | Q17: 46 | R17: 0 | S17: 0 | T17: 0 | U17: 1 | V17: 0 | W17: 7 | X17: 1 | Y17: 0 | Z17: 0 | AA17: 0 | AB17: 0 | AC17: 0 | AD17: 0 | AE17: 1 | AF17: 0 | AG17: 0 | AH17: 1 | AI17: 1 | AJ17: 238 | AK17: 0 | AL17: 0 | AM17: 50 | AN17: 53 | AO17: 48 | AP17: 47 | AQ17: =I17+J17 -> 47 | AR17: =IF(AQ17>0,I17/AQ17,"") -> 0.042553191 | AS17: =IF((P17+Q17)>0,P17/(P17+Q17),"") -> 0.041666667 | AT17: =IF(AND(ISNUMBER(AR17),ISNUMBER(AS17)),(AR17-AS17)*100,"") -> 0.088652482 | AU17: =IF(G17>0,I17/G17*1000,"") -> 2.2962113 | AV17: =IF(G17>0,H17/G17*10000,"") -> 11.481056 | AW17: =IF(G17>0,W17/G17*10000,"") -> 80.367394 | AX17: =IF(I17>0,K17/I17*100,"") -> 300 | AY17: =IF(AQ17>=100,"ok",IF(AQ17>0,"effectif faible (<100)","aucune association")) -> effectif faible (<100)
A18: 95042 | B18: Baillet-en-France | C18: Domont | D18: liste subventions 2025 | E18: CC Carnelle Pays-de-France | F18: Ceintures urbaines | G18: 2021 | H18: 3 | I18: 134 | J18: 182 | K18: 15 | L18: 1 | M18: 0 | N18: 1 | O18: 3 | P18: 183 | Q18: 145 | R18: 0 | S18: 0 | T18: 0 | U18: 2 | V18: 0 | W18: 5 | X18: 0 | Y18: 0 | Z18: 1 | AA18: 0 | AB18: 0 | AC18: 0 | AD18: 0 | AE18: 2 | AF18: 1 | AG18: 1 | AH18: 2 | AI18: 3 | AJ18: 316 | AK18: 327 | AL18: 319 | AM18: 346 | AN18: 319 | AO18: 328 | AP18: 316 | AQ18: =I18+J18 -> 316 | AR18: =IF(AQ18>0,I18/AQ18,"") -> 0.42405063 | AS18: =IF((P18+Q18)>0,P18/(P18+Q18),"") -> 0.55792683 | AT18: =IF(AND(ISNUMBER(AR18),ISNUMBER(AS18)),(AR18-AS18)*100,"") -> -13.38762 | AU18: =IF(G18>0,I18/G18*1000,"") -> 66.30381 | AV18: =IF(G18>0,H18/G18*10000,"") -> 14.844137 | AW18: =IF(G18>0,W18/G18*10000,"") -> 24.740228 | AX18: =IF(I18>0,K18/I18*100,"") -> 11.19403 | AY18: =IF(AQ18>=100,"ok",IF(AQ18>0,"effectif faible (<100)","aucune association")) -> ok
A19: 95046 | B19: Banthelu | C19: Vauréal | D19: imputé (commune voisine la plus proche) | E19: CC du Vexin-Val de Seine | F19: Rural à habitat dispersé | G19: 146 | H19: 0 | I19: 0 | J19: 0 | K19: 0 | L19: 0 | M19: 0 | N19: 0 | O19: 0 | P19: 0 | Q19: 0 | R19: 0 | S19: 0 | T19: 0 | U19: 0 | V19: 0 | W19: 1 | X19: 0 | Y19: 0 | Z19: 0 | AA19: 0 | AB19: 0 | AC19: 0 | AD19: 0 | AE19: 0 | AF19: 0 | AG19: 0 | AH19: 0 | AI19: 0 | AJ19: 0 | AK19: 0 | AL19: 0 | AM19: 0 | AN19: 0 | AO19: 0 | AP19: 0 | AQ19: =I19+J19 -> 0 | AR19: =IF(AQ19>0,I19/AQ19,"") | AS19: =IF((P19+Q19)>0,P19/(P19+Q19),"") | AT19: =IF(AND(ISNUMBER(AR19),ISNUMBER(AS19)),(AR19-AS19)*100,"") | AU19: =IF(G19>0,I19/G19*1000,"") -> 0 | AV19: =IF(G19>0,H19/G19*10000,"") -> 0 | AW19: =IF(G19>0,W19/G19*10000,"") -> 68.493151 | AX19: =IF(I19>0,K19/I19*100,"") | AY19: =IF(AQ19>=100,"ok",IF(AQ19>0,"effectif faible (<100)","aucune association")) -> aucune association
... A41: 95134 | B41: Champagne-sur-Oise | C41: L'Isle-Adam | D41: liste subventions 2025 | E41: CC du Haut Val d'Oise | F41: Ceintures urbaines | G41: 5036 | H41: 3 | I41: 55 | J41: 183 | K41: 16 | L41: 3 | M41: 1 | N41: 0 | O41: 1 | P41: 52 | Q41: 133 | R41: 0 | S41: 0 | T41: 0 | U41: 3 | V41: 0 | W41: 9 | X41: 3 | Y41: 0 | Z41: 0 | AA41: 0 | AB41: 0 | AC41: 0 | AD41: 0 | AE41: 2 | AF41: 2 | AG41: 2 | AH41: 2 | AI41: 2 | AJ41: 268 | AK41: 205 | AL41: 162 | AM41: 171 | AN41: 151 | AO41: 185 | AP41: 238 | AQ41: =I41+J41 -> 238 | AR41: =IF(AQ41>0,I41/AQ41,"") -> 0.23109244 | AS41: =IF((P41+Q41)>0,P41/(P41+Q41),"") -> 0.28108108 | AT41: =IF(AND(ISNUMBER(AR41),ISNUMBER(AS41)),(AR41-AS41)*100,"") -> -4.9988644 | AU41: =IF(G41>0,I41/G41*1000,"") -> 10.921366 | AV41: =IF(G41>0,H41/G41*10000,"") -> 5.9571088 | AW41: =IF(G41>0,W41/G41*10000,"") -> 17.871326 | AX41: =IF(I41>0,K41/I41*100,"") -> 29.090909 | AY41: =IF(AQ41>=100,"ok",IF(AQ41>0,"effectif faible (<100)","aucune association")) -> ok
A42: 95141 | B42: Charmont | C42: Vauréal | D42: imputé (commune voisine la plus proche) | E42: CC du Vexin-Val de Seine | G42: 32 | H42: 0 | I42: 0 | J42: 0 | K42: 0 | L42: 0 | M42: 0 | N42: 0 | O42: 0 | P42: 0 | Q42: 0 | R42: 0 | S42: 0 | T42: 0 | U42: 0 | V42: 0 | W42: 0 | X42: 0 | Y42: 0 | Z42: 0 | AA42: 0 | AB42: 0 | AC42: 0 | AD42: 0 | AE42: 0 | AF42: 0 | AG42: 0 | AH42: 0 | AI42: 0 | AJ42: 0 | AK42: 0 | AL42: 0 | AM42: 0 | AN42: 0 | AO42: 0 | AP42: 0 | AQ42: =I42+J42 -> 0 | AR42: =IF(AQ42>0,I42/AQ42,"") | AS42: =IF((P42+Q42)>0,P42/(P42+Q42),"") | AT42: =IF(AND(ISNUMBER(AR42),ISNUMBER(AS42)),(AR42-AS42)*100,"") | AU42: =IF(G42>0,I42/G42*1000,"") -> 0 | AV42: =IF(G42>0,H42/G42*10000,"") -> 0 | AW42: =IF(G42>0,W42/G42*10000,"") -> 0 | AX42: =IF(I42>0,K42/I42*100,"") | AY42: =IF(AQ42>=100,"ok",IF(AQ42>0,"effectif faible (<100)","aucune association")) -> aucune association
A43: 95142 | B43: Chars | C43: Pontoise | D43: liste subventions 2025 | E43: CC Vexin Centre | F43: Bourgs ruraux | G43: 2006 | H43: 2 | I43: 30 | J43: 90 | K43: 45 | L43: 0 | M43: 1 | N43: 0 | O43: 2 | P43: 34 | Q43: 87 | R43: 1 | S43: 159 | T43: 20 | U43: 2 | V43: 1 | W43: 5 | X43: 1 | Y43: 0 | Z43: 0 | AA43: 0 | AB43: 0 | AC43: 0 | AD43: 0 | AE43: 1 | AF43: 1 | AG43: 1 | AH43: 1 | AI43: 2 | AJ43: 17 | AK43: 22 | AL43: 18 | AM43: 19 | AN43: 75 | AO43: 121 | AP43: 120 | AQ43: =I43+J43 -> 120 | AR43: =IF(AQ43>0,I43/AQ43,"") -> 0.25 | AS43: =IF((P43+Q43)>0,P43/(P43+Q43),"") -> 0.28099174 | AT43: =IF(AND(ISNUMBER(AR43),ISNUMBER(AS43)),(AR43-AS43)*100,"") -> -3.0991736 | AU43: =IF(G43>0,I43/G43*1000,"") -> 14.955135 | AV43: =IF(G43>0,H43/G43*10000,"") -> 9.9700897 | AW43: =IF(G43>0,W43/G43*10000,"") -> 24.925224 | AX43: =IF(I43>0,K43/I43*100,"") -> 150 | AY43: =IF(AQ43>=100,"ok",IF(AQ43>0,"effectif faible (<100)","aucune association")) -> ok
A44: 95149 | B44: Chaumontel | C44: Fosses | D44: liste subventions 2025 | E44: CC Carnelle Pays-de-France | F44: Petites villes | G44: 3332 | H44: 3 | I44: 347 | J44: 106 | K44: 8 | L44: 4 | M44: 2 | N44: 1 | O44: 4 | P44: 442 | Q44: 117 | R44: 0 | S44: 0 | T44: 0 | U44: 3 | V44: 0 | W44: 5 | X44: 1 | Y44: 0 | Z44: 0 | AA44: 0 | AB44: 0 | AC44: 0 | AD44: 0 | AE44: 4 | AF44: 3 | AG44: 4 | AH44: 4 | AI44: 3 | AJ44: 543 | AK44: 497 | AL44: 549 | AM44: 525 | AN44: 469 | AO44: 559 | AP44: 453 | AQ44: =I44+J44 -> 453 | AR44: =IF(AQ44>0,I44/AQ44,"") -> 0.76600442 | AS44: =IF((P44+Q44)>0,P44/(P44+Q44),"") -> 0.79069767 | AT44: =IF(AND(ISNUMBER(AR44),ISNUMBER(AS44)),(AR44-AS44)*100,"") -> -2.4693259 | AU44: =IF(G44>0,I44/G44*1000,"") -> 104.14166 | AV44: =IF(G44>0,H44/G44*10000,"") -> 9.0036014 | AW44: =IF(G44>0,W44/G44*10000,"") -> 15.006002 | AX44: =IF(I44>0,K44/I44*100,"") -> 2.3054755 | AY44: =IF(AQ44>=100,"ok",IF(AQ44>0,"effectif faible (<100)","aucune association")) -> ok
A45: 95150 | B45: Chaussy | C45: Vauréal | D45: liste subventions 2025 | E45: CC du Vexin-Val de Seine | F45: Rural à habitat dispersé | G45: 631 | H45: 1 | I45: 82 | J45: 223 | K45: 8 | L45: 10 | M45: 0 | N45: 0 | O45: 1 | P45: 92 | Q45: 218 | R45: 1 | S45: 69 | T45: 10 | U45: 1 | V45: 1 | W45: 5 | X45: 0 | Y45: 0 | Z45: 0 | AA45: 0 | AB45: 0 | AC45: 0 | AD45: 0 | AE45: 1 | AF45: 1 | AG45: 1 | AH45: 1 | AI45: 1 | AJ45: 512 | AK45: 350 | AL45: 340 | AM45: 340 | AN45: 297 | AO45: 310 | AP45: 305 | AQ45: =I45+J45 -> 305 | AR45: =IF(AQ45>0,I45/AQ45,"") -> 0.26885246 | AS45: =IF((P45+Q45)>0,P45/(P45+Q45),"") -> 0.29677419 | AT45: =IF(AND(ISNUMBER(AR45),ISNUMBER(AS45)),(AR45-AS45)*100,"") -> -2.7921735 | AU45: =IF(G45>0,I45/G45*1000,"") -> 129.95246 | AV45: =IF(G45>0,H45/G45*10000,"") -> 15.847861 | AW45: =IF(G45>0,W45/G45*10000,"") -> 79.239303 | AX45: =IF(I45>0,K45/I45*100,"") -> 9.7560976 | AY45: =IF(AQ45>=100,"ok",IF(AQ45>0,"effectif faible (<100)","aucune association")) -> ok
A46: 95151 | B46: Chauvry | C46: Domont | D46: imputé (commune voisine la plus proche) | E46: CC de la Vallée de l'Oise et des Trois Forêts | F46: Rural à habitat dispersé | G46: 297 | H46: 0 | I46: 0 | J46: 0 | K46: 0 | L46: 0 | M46: 0 | N46: 0 | O46: 0 | P46: 0 | Q46: 0 | R46: 0 | S46: 0 | T46: 0 | U46: 0 | V46: 0 | W46: 1 | X46: 0 | Y46: 0 | Z46: 0 | AA46: 0 | AB46: 0 | AC46: 0 | AD46: 0 | AE46: 0 | AF46: 0 | AG46: 0 | AH46: 0 | AI46: 0 | AJ46: 0 | AK46: 0 | AL46: 0 | AM46: 0 | AN46: 0 | AO46: 0 | AP46: 0 | AQ46: =I46+J46 -> 0 | AR46: =IF(AQ46>0,I46/AQ46,"") | AS46: =IF((P46+Q46)>0,P46/(P46+Q46),"") | AT46: =IF(AND(ISNUMBER(AR46),ISNUMBER(AS46)),(AR46-AS46)*100,"") | AU46: =IF(G46>0,I46/G46*1000,"") -> 0 | AV46: =IF(G46>0,H46/G46*10000,"") -> 0 | AW46: =IF(G46>0,W46/G46*10000,"") -> 33.670034 | AX46: =IF(I46>0,K46/I46*100,"") | AY46: =IF(AQ46>=100,"ok",IF(AQ46>0,"effectif faible (<100)","aucune association")) -> aucune association
A47: 95154 | B47: Chennevières-lès-Louvres | C47: Goussainville | D47: imputé (commune voisine la plus proche) | E47: CA Roissy Pays de France | F47: Rural à habitat dispersé | G47: 282 | H47: 0 | I47: 0 | J47: 0 | K47: 0 | L47: 0 | M47: 0 | N47: 0 | O47: 0 | P47: 0 | Q47: 0 | R47: 0 | S47: 0 | T47: 0 | U47: 0 | V47: 0 | W47: 2 | X47: 0 | Y47: 0 | Z47: 0 | AA47: 0 | AB47: 0 | AC47: 0 | AD47: 0 | AE47: 0 | AF47: 0 | AG47: 0 | AH47: 0 | AI47: 0 | AJ47: 0 | AK47: 0 | AL47: 0 | AM47: 0 | AN47: 0 | AO47: 0 | AP47: 0 | AQ47: =I47+J47 -> 0 | AR47: =IF(AQ47>0,I47/AQ47,"") | AS47: =IF((P47+Q47)>0,P47/(P47+Q47),"") | AT47: =IF(AND(ISNUMBER(AR47),ISNUMBER(AS47)),(AR47-AS47)*100,"") | AU47: =IF(G47>0,I47/G47*1000,"") -> 0 | AV47: =IF(G47>0,H47/G47*10000,"") -> 0 | AW47: =IF(G47>0,W47/G47*10000,"") -> 70.921986 | AX47: =IF(I47>0,K47/I47*100,"") | AY47: =IF(AQ47>=100,"ok",IF(AQ47>0,"effectif faible (<100)","aucune association")) -> aucune association
A48: 95144 | B48: Châtenay-en-France | C48: Fosses | D48: imputé (commune voisine la plus proche) | E48: CC Carnelle Pays-de-France | G48: 68 | H48: 0 | I48: 0 | J48: 0 | K48: 0 | L48: 0 | M48: 0 | N48: 0 | O48: 0 | P48: 0 | Q48: 0 | R48: 0 | S48: 0 | T48: 0 | U48: 0 | V48: 0 | W48: 0 | X48: 0 | Y48: 0 | Z48: 0 | AA48: 0 | AB48: 0 | AC48: 0 | AD48: 0 | AE48: 0 | AF48: 0 | AG48: 0 | AH48: 0 | AI48: 0 | AJ48: 0 | AK48: 0 | AL48: 0 | AM48: 0 | AN48: 0 | AO48: 0 | AP48: 0 | AQ48: =I48+J48 -> 0 | AR48: =IF(AQ48>0,I48/AQ48,"") | AS48: =IF((P48+Q48)>0,P48/(P48+Q48),"") | AT48: =IF(AND(ISNUMBER(AR48),ISNUMBER(AS48)),(AR48-AS48)*100,"") | AU48: =IF(G48>0,I48/G48*1000,"") -> 0 | AV48: =IF(G48>0,H48/G48*10000,"") -> 0 | AW48: =IF(G48>0,W48/G48*10000,"") -> 0 | AX48: =IF(I48>0,K48/I48*100,"") | AY48: =IF(AQ48>=100,"ok",IF(AQ48>0,"effectif faible (<100)","aucune association")) -> aucune association
A49: 95157 | B49: Chérence | C49: Vauréal | D49: liste subventions 2025 | E49: CC du Vexin-Val de Seine | F49: Rural à habitat dispersé | G49: 137 | H49: 1 | I49: 75 | J49: 188 | K49: 141 | L49: 3 | M49: 0 | N49: 0 | O49: 1 | P49: 73 | Q49: 210 | R49: 0 | S49: 0 | T49: 0 | U49: 1 | V49: 0 | W49: 3 | X49: 0 | Y49: 0 | Z49: 1 | AA49: 0 | AB49: 1 | AC49: 0 | AD49: 0 | AE49: 1 | AF49: 1 | AG49: 1 | AH49: 1 | AI49: 1 | AJ49: 236 | AK49: 256 | AL49: 293 | AM49: 243 | AN49: 272 | AO49: 283 | AP49: 263 | AQ49: =I49+J49 -> 263 | AR49: =IF(AQ49>0,I49/AQ49,"") -> 0.2851711 | AS49: =IF((P49+Q49)>0,P49/(P49+Q49),"") -> 0.25795053 | AT49: =IF(AND(ISNUMBER(AR49),ISNUMBER(AS49)),(AR49-AS49)*100,"") -> 2.7220573 | AU49: =IF(G49>0,I49/G49*1000,"") -> 547.44526 | AV49: =IF(G49>0,H49/G49*10000,"") -> 72.992701 | AW49: =IF(G49>0,W49/G49*10000,"") -> 218.9781 | AX49: =IF(I49>0,K49/I49*100,"") -> 188 | AY49: =IF(AQ49>=100,"ok",IF(AQ49>0,"effectif faible (<100)","aucune association")) -> ok
A50: 95166 | B50: Cléry-en-Vexin | C50: Vauréal | D50: liste subventions 2025 | E50: CC Vexin Centre | F50: Rural à habitat dispersé | G50: 476 | H50: 0 | I50: 0 | J50: 0 | K50: 0 | L50: 0 | M50: 0 | N50: 0 | O50: 1 | P50: 72 | Q50: 118 | R50: 1 | S50: 45 | T50: 1 | U50: 1 | V50: 1 | W50: 1 | X50: 0 | Y50: 0 | Z50: 0 | AA50: 0 | AB50: 0 | AC50: 0 | AD50: 0 | AE50: 1 | AF50: 1 | AG50: 1 | AH50: 1 | AI50: 1 | AJ50: 14 | AK50: 18 | AL50: 13 | AM50: 18 | AN50: 20 | AO50: 190 | AP50: 0 | AQ50: =I50+J50 -> 0 | AR50: =IF(AQ50>0,I50/AQ50,"") | AS50: =IF((P50+Q50)>0,P50/(P50+Q50),"") -> 0.37894737 | AT50: =IF(AND(ISNUMBER(AR50),ISNUMBER(AS50)),(AR50-AS50)*100,"") | AU50: =IF(G50>0,I50/G50*1000,"") -> 0 | AV50: =IF(G50>0,H50/G50*10000,"") -> 0 | AW50: =IF(G50>0,W50/G50*10000,"") -> 21.008403 | AX50: =IF(I50>0,K50/I50*100,"") | AY50: =IF(AQ50>=100,"ok",IF(AQ50>0,"effectif faible (<100)","aucune association")) -> aucune association
A51: 95169 | B51: Commeny | C51: Vauréal | D51: imputé (commune voisine la plus proche) | E51: CC Vexin Centre | F51: Rural à habitat dispersé | G51: 646 | H51: 0 | I51: 0 | J51: 0 | K51: 0 | L51: 0 | M51: 0 | N51: 0 | O51: 0 | P51: 0 | Q51: 0 | R51: 0 | S51: 0 | T51: 0 | U51: 0 | V51: 0 | W51: 5 | X51: 1 | Y51: 0 | Z51: 0 | AA51: 0 | AB51: 0 | AC51: 0 | AD51: 0 | AE51: 0 | AF51: 0 | AG51: 0 | AH51: 0 | AI51: 0 | AJ51: 0 | AK51: 0 | AL51: 0 | AM51: 0 | AN51: 0 | AO51: 0 | AP51: 0 | AQ51: =I51+J51 -> 0 | AR51: =IF(AQ51>0,I51/AQ51,"") | AS51: =IF((P51+Q51)>0,P51/(P51+Q51),"") | AT51: =IF(AND(ISNUMBER(AR51),ISNUMBER(AS51)),(AR51-AS51)*100,"") | AU51: =IF(G51>0,I51/G51*1000,"") -> 0 | AV51: =IF(G51>0,H51/G51*10000,"") -> 0 | AW51: =IF(G51>0,W51/G51*10000,"") -> 77.399381 | AX51: =IF(I51>0,K51/I51*100,"") | AY51: =IF(AQ51>=100,"ok",IF(AQ51>0,"effectif faible (<100)","aucune association")) -> aucune association
A52: 95170 | B52: Condécourt | C52: Vauréal | D52: imputé (commune voisine la plus proche) | E52: CC Vexin Centre | F52: Rural à habitat dispersé | G52: 564 | H52: 0 | I52: 0 | J52: 0 | K52: 0 | L52: 0 | M52: 0 | N52: 0 | O52: 0 | P52: 0 | Q52: 0 | R52: 0 | S52: 0 | T52: 0 | U52: 0 | V52: 0 | W52: 2 | X52: 1 | Y52: 0 | Z52: 0 | AA52: 0 | AB52: 0 | AC52: 0 | AD52: 0 | AE52: 0 | AF52: 0 | AG52: 0 | AH52: 0 | AI52: 0 | AJ52: 0 | AK52: 0 | AL52: 0 | AM52: 0 | AN52: 0 | AO52: 0 | AP52: 0 | AQ52: =I52+J52 -> 0 | AR52: =IF(AQ52>0,I52/AQ52,"") | AS52: =IF((P52+Q52)>0,P52/(P52+Q52),"") | AT52: =IF(AND(ISNUMBER(AR52),ISNUMBER(AS52)),(AR52-AS52)*100,"") | AU52: =IF(G52>0,I52/G52*1000,"") -> 0 | AV52: =IF(G52>0,H52/G52*10000,"") -> 0 | AW52: =IF(G52>0,W52/G52*10000,"") -> 35.460993 | AX52: =IF(I52>0,K52/I52*100,"") | AY52: =IF(AQ52>=100,"ok",IF(AQ52>0,"effectif faible (<100)","aucune association")) -> aucune association
A53: 95176 | B53: Cormeilles-en-Parisis | C53: Franconville | D53: liste subventions 2025 | E53: CA Val Parisis | F53: Grands centres urbains | G53: 27292 | H53: 1 | I53: 3779 | J53: 2055 | K53: 203 | L53: 46 | M53: 0 | N53: 1 | O53: 2 | P53: 3683 | Q53: 2055 | R53: 1 | S53: 155 | T53: 3 | U53: 1 | V53: 1 | W53: 28 | X53: 10 | Y53: 1 | Z53: 0 | AA53: 0 | AB53: 0 | AC53: 1 | AD53: 0 | AE53: 1 | AF53: 2 | AG53: 2 | AH53: 2 | AI53: 2 | AJ53: 3399 | AK53: 4103 | AL53: 4063 | AM53: 3294 | AN53: 5033 | AO53: 5738 | AP53: 5834 | AQ53: =I53+J53 -> 5834 | AR53: =IF(AQ53>0,I53/AQ53,"") -> 0.64775454 | AS53: =IF((P53+Q53)>0,P53/(P53+Q53),"") -> 0.64186128 | AT53: =IF(AND(ISNUMBER(AR53),ISNUMBER(AS53)),(AR53-AS53)*100,"") -> 0.58932666 | AU53: =IF(G53>0,I53/G53*1000,"") -> 138.46548 | AV53: =IF(G53>0,H53/G53*10000,"") -> 0.36640774 | AW53: =IF(G53>0,W53/G53*10000,"") -> 10.259417 | AX53: =IF(I53>0,K53/I53*100,"") -> 5.3717915 | AY53: =IF(AQ53>=100,"ok",IF(AQ53>0,"effectif faible (<100)","aucune association")) -> ok
A54: 95177 | B54: Cormeilles-en-Vexin | C54: Pontoise | D54: imputé (commune voisine la plus proche) | E54: CC Vexin Centre | F54: Bourgs ruraux | G54: 1297 | H54: 0 | I54: 0 | J54: 0 | K54: 0 | L54: 0 | M54: 0 | N54: 0 | O54: 0 | P54: 0 | Q54: 0 | R54: 0 | S54: 0 | T54: 0 | U54: 0 | V54: 0 | W54: 6 | X54: 1 | Y54: 0 | Z54: 0 | AA54: 0 | AB54: 0 | AC54: 0 | AD54: 0 | AE54: 0 | AF54: 0 | AG54: 0 | AH54: 0 | AI54: 0 | AJ54: 0 | AK54: 0 | AL54: 0 | AM54: 0 | AN54: 0 | AO54: 0 | AP54: 0 | AQ54: =I54+J54 -> 0 | AR54: =IF(AQ54>0,I54/AQ54,"") | AS54: =IF((P54+Q54)>0,P54/(P54+Q54),"") | AT54: =IF(AND(ISNUMBER(AR54),ISNUMBER(AS54)),(AR54-AS54)*100,"") | AU54: =IF(G54>0,I54/G54*1000,"") -> 0 | AV54: =IF(G54>0,H54/G54*10000,"") -> 0 | AW54: =IF(G54>0,W54/G54*10000,"") -> 46.260601 | AX54: =IF(I54>0,K54/I54*100,"") | AY54: =IF(AQ54>=100,"ok",IF(AQ54>0,"effectif faible (<100)","aucune association")) -> aucune association
A55: 95181 | B55: Courcelles-sur-Viosne | C55: Pontoise | D55: imputé (commune voisine la plus proche) | E55: CC Vexin Centre | F55: Rural à habitat dispersé | G55: 310 | H55: 0 | I55: 0 | J55: 0 | K55: 0 | L55: 0 | M55: 0 | N55: 0 | O55: 0 | P55: 0 | Q55: 0 | R55: 0 | S55: 0 | T55: 0 | U55: 0 | V55: 0 | W55: 2 | X55: 0 | Y55: 0 | Z55: 0 | AA55: 0 | AB55: 0 | AC55: 0 | AD55: 0 | AE55: 0 | AF55: 0 | AG55: 0 | AH55: 0 | AI55: 0 | AJ55: 0 | AK55: 0 | AL55: 0 | AM55: 0 | AN55: 0 | AO55: 0 | AP55: 0 | AQ55: =I55+J55 -> 0 | AR55: =IF(AQ55>0,I55/AQ55,"") | AS55: =IF((P55+Q55)>0,P55/(P55+Q55),"") | AT55: =IF(AND(ISNUMBER(AR55),ISNUMBER(AS55)),(AR55-AS55)*100,"") | AU55: =IF(G55>0,I55/G55*1000,"") -> 0 | AV55: =IF(G55>0,H55/G55*10000,"") -> 0 | AW55: =IF(G55>0,W55/G55*10000,"") -> 64.516129 | AX55: =IF(I55>0,K55/I55*100,"") | AY55: =IF(AQ55>=100,"ok",IF(AQ55>0,"effectif faible (<100)","aucune association")) -> aucune association
A56: 95183 | B56: Courdimanche | C56: Vauréal | D56: liste subventions 2025 | E56: CA de Cergy-Pontoise | F56: Grands centres urbains | G56: 7311 | H56: 4 | I56: 333 | J56: 645 | K56: 59 | L56: 11 | M56: 1 | N56: 2 | O56: 5 | P56: 343 | Q56: 682 | R56: 1 | S56: 416 | T56: 20 | U56: 5 | V56: 1 | W56: 7 | X56: 2 | Y56: 0 | Z56: 0 | AA56: 0 | AB56: 1 | AC56: 0 | AD56: 0 | AE56: 4 | AF56: 5 | AG56: 5 | AH56: 4 | AI56: 5 | AJ56: 494 | AK56: 996 | AL56: 952 | AM56: 757 | AN56: 918 | AO56: 1025 | AP56: 978 | AQ56: =I56+J56 -> 978 | AR56: =IF(AQ56>0,I56/AQ56,"") -> 0.3404908 | AS56: =IF((P56+Q56)>0,P56/(P56+Q56),"") -> 0.33463415 | AT56: =IF(AND(ISNUMBER(AR56),ISNUMBER(AS56)),(AR56-AS56)*100,"") -> 0.58566512 | AU56: =IF(G56>0,I56/G56*1000,"") -> 45.547805 | AV56: =IF(G56>0,H56/G56*10000,"") -> 5.4712078 | AW56: =IF(G56>0,W56/G56*10000,"") -> 9.5746136 | AX56: =IF(I56>0,K56/I56*100,"") -> 17.717718 | AY56: =IF(AQ56>=100,"ok",IF(AQ56>0,"effectif faible (<100)","aucune association")) -> ok
A57: 95197 | B57: Deuil-la-Barre | C57: Deuil-la-Barre | D57: liste subventions 2025 | E57: CA Plaine Vallée | F57: Grands centres urbains | G57: 23099 | H57: 6 | I57: 1140 | J57: 1428 | K57: 134 | L57: 16 | M57: 1 | N57: 2 | O57: 8 | P57: 1365 | Q57: 1771 | R57: 2 | S57: 236 | T57: 7 | U57: 6 | V57: 2 | W57: 19 | X57: 10 | Y57: 0 | Z57: 0 | AA57: 1 | AB57: 0 | AC57: 0 | AD57: 0 | AE57: 8 | AF57: 9 | AG57: 9 | AH57: 8 | AI57: 8 | AJ57: 2377 | AK57: 3056 | AL57: 2952 | AM57: 2643 | AN57: 3079 | AO57: 3136 | AP57: 2568 | AQ57: =I57+J57 -> 2568 | AR57: =IF(AQ57>0,I57/AQ57,"") -> 0.44392523 | AS57: =IF((P57+Q57)>0,P57/(P57+Q57),"") -> 0.43526786 | AT57: =IF(AND(ISNUMBER(AR57),ISNUMBER(AS57)),(AR57-AS57)*100,"") -> 0.86573765 | AU57: =IF(G57>0,I57/G57*1000,"") -> 49.352786 | AV57: =IF(G57>0,H57/G57*10000,"") -> 2.597515 | AW57: =IF(G57>0,W57/G57*10000,"") -> 8.2254643 | AX57: =IF(I57>0,K57/I57*100,"") -> 11.754386 | AY57: =IF(AQ57>=100,"ok",IF(AQ57>0,"effectif faible (<100)","aucune association")) -> ok
A58: 95199 | B58: Domont | C58: Domont | D58: liste subventions 2025 | E58: CA Plaine Vallée | F58: Grands centres urbains | G58: 16065 | H58: 12 | I58: 892 | J58: 1742 | K58: 230 | L58: 28 | M58: 3 | N58: 1 | O58: 12 | P58: 842 | Q58: 1616 | R58: 2 | S58: 401 | T58: 10 | U58: 13 | V58: 2 | W58: 13 | X58: 2 | Y58: 0 | Z58: 0 | AA58: 0 | AB58: 0 | AC58: 0 | AD58: 0 | AE58: 10 | AF58: 11 | AG58: 13 | AH58: 12 | AI58: 11 | AJ58: 2052 | AK58: 2020 | AL58: 2497 | AM58: 2621 | AN58: 2414 | AO58: 2458 | AP58: 2634 | AQ58: =I58+J58 -> 2634 | AR58: =IF(AQ58>0,I58/AQ58,"") -> 0.33864844 | AS58: =IF((P58+Q58)>0,P58/(P58+Q58),"") -> 0.34255492 | AT58: =IF(AND(ISNUMBER(AR58),ISNUMBER(AS58)),(AR58-AS58)*100,"") -> -0.39064793 | AU58: =IF(G58>0,I58/G58*1000,"") -> 55.524432 | AV58: =IF(G58>0,H58/G58*10000,"") -> 7.4696545 | AW58: =IF(G58>0,W58/G58*10000,"") -> 8.0921257 | AX58: =IF(I58>0,K58/I58*100,"") -> 25.784753 | AY58: =IF(AQ58>=100,"ok",IF(AQ58>0,"effectif faible (<100)","aucune association")) -> ok
A59: 95203 | B59: Eaubonne | C59: Ermont | D59: liste subventions 2025 | E59: CA Val Parisis | F59: Grands centres urbains | G59: 26211 | H59: 7 | I59: 1011 | J59: 583 | K59: 114 | L59: 23 | M59: 0 | N59: 3 | O59: 7 | P59: 1114 | Q59: 516 | R59: 1 | S59: 109 | T59: 4 | U59: 8 | V59: 1 | W59: 20 | X59: 0 | Y59: 1 | Z59: 4 | AA59: 1 | AB59: 4 | AC59: 0 | AD59: 0 | AE59: 6 | AF59: 6 | AG59: 7 | AH59: 7 | AI59: 6 | AJ59: 4317 | AK59: 4382 | AL59: 3698 | AM59: 1253 | AN59: 779 | AO59: 1630 | AP59: 1594 | AQ59: =I59+J59 -> 1594 | AR59: =IF(AQ59>0,I59/AQ59,"") -> 0.63425345 | AS59: =IF((P59+Q59)>0,P59/(P59+Q59),"") -> 0.68343558 | AT59: =IF(AND(ISNUMBER(AR59),ISNUMBER(AS59)),(AR59-AS59)*100,"") -> -4.9182132 | AU59: =IF(G59>0,I59/G59*1000,"") -> 38.571592 | AV59: =IF(G59>0,H59/G59*10000,"") -> 2.6706345 | AW59: =IF(G59>0,W59/G59*10000,"") -> 7.6303842 | AX59: =IF(I59>0,K59/I59*100,"") -> 11.275964 | AY59: =IF(AQ59>=100,"ok",IF(AQ59>0,"effectif faible (<100)","aucune association")) -> ok
A60: 95210 | B60: Enghien-les-Bains | C60: Montmorency | D60: liste subventions 2025 | E60: CA Plaine Vallée | F60: Grands centres urbains | G60: 11432 | H60: 8 | I60: 748 | J60: 624 | K60: 180 | L60: 14 | M60: 3 | N60: 3 | O60: 8 | P60: 769 | Q60: 602 | R60: 0 | S60: 0 | T60: 0 | U60: 9 | V60: 0 | W60: 19 | X60: 7 | Y60: 0 | Z60: 0 | AA60: 0 | AB60: 2 | AC60: 1 | AD60: 0 | AE60: 6 | AF60: 7 | AG60: 7 | AH60: 8 | AI60: 9 | AJ60: 841 | AK60: 1028 | AL60: 783 | AM60: 1055 | AN60: 1221 | AO60: 1371 | AP60: 1372 | AQ60: =I60+J60 -> 1372 | AR60: =IF(AQ60>0,I60/AQ60,"") -> 0.5451895 | AS60: =IF((P60+Q60)>0,P60/(P60+Q60),"") -> 0.56090445 | AT60: =IF(AND(ISNUMBER(AR60),ISNUMBER(AS60)),(AR60-AS60)*100,"") -> -1.5714945 | AU60: =IF(G60>0,I60/G60*1000,"") -> 65.430371 | AV60: =IF(G60>0,H60/G60*10000,"") -> 6.9979006 | AW60: =IF(G60>0,W60/G60*10000,"") -> 16.620014 | AX60: =IF(I60>0,K60/I60*100,"") -> 24.064171 | AY60: =IF(AQ60>=100,"ok",IF(AQ60>0,"effectif faible (<100)","aucune association")) -> ok
... A78: 95298 | B78: Haravilliers | C78: Pontoise | D78: liste subventions 2025 | E78: CC Vexin Centre | F78: Rural à habitat dispersé | G78: 589 | H78: 1 | I78: 158 | J78: 61 | K78: 6 | L78: 2 | M78: 0 | N78: 1 | O78: 1 | P78: 174 | Q78: 72 | R78: 0 | S78: 0 | T78: 0 | U78: 1 | V78: 0 | W78: 2 | X78: 1 | Y78: 0 | Z78: 0 | AA78: 0 | AB78: 0 | AC78: 0 | AD78: 0 | AE78: 1 | AF78: 1 | AG78: 1 | AH78: 1 | AI78: 1 | AJ78: 100 | AK78: 0 | AL78: 0 | AM78: 0 | AN78: 0 | AO78: 246 | AP78: 219 | AQ78: =I78+J78 -> 219 | AR78: =IF(AQ78>0,I78/AQ78,"") -> 0.72146119 | AS78: =IF((P78+Q78)>0,P78/(P78+Q78),"") -> 0.70731707 | AT78: =IF(AND(ISNUMBER(AR78),ISNUMBER(AS78)),(AR78-AS78)*100,"") -> 1.4144114 | AU78: =IF(G78>0,I78/G78*1000,"") -> 268.25127 | AV78: =IF(G78>0,H78/G78*10000,"") -> 16.977929 | AW78: =IF(G78>0,W78/G78*10000,"") -> 33.955857 | AX78: =IF(I78>0,K78/I78*100,"") -> 3.7974684 | AY78: =IF(AQ78>=100,"ok",IF(AQ78>0,"effectif faible (<100)","aucune association")) -> ok
A79: 95301 | B79: Haute-Isle | C79: Vauréal | D79: imputé (commune voisine la plus proche) | E79: CC du Vexin-Val de Seine | G79: 293 | H79: 0 | I79: 0 | J79: 0 | K79: 0 | L79: 0 | M79: 0 | N79: 0 | O79: 0 | P79: 0 | Q79: 0 | R79: 0 | S79: 0 | T79: 0 | U79: 0 | V79: 0 | W79: 0 | X79: 0 | Y79: 0 | Z79: 0 | AA79: 0 | AB79: 0 | AC79: 0 | AD79: 0 | AE79: 0 | AF79: 0 | AG79: 0 | AH79: 0 | AI79: 0 | AJ79: 0 | AK79: 0 | AL79: 0 | AM79: 0 | AN79: 0 | AO79: 0 | AP79: 0 | AQ79: =I79+J79 -> 0 | AR79: =IF(AQ79>0,I79/AQ79,"") | AS79: =IF((P79+Q79)>0,P79/(P79+Q79),"") | AT79: =IF(AND(ISNUMBER(AR79),ISNUMBER(AS79)),(AR79-AS79)*100,"") | AU79: =IF(G79>0,I79/G79*1000,"") -> 0 | AV79: =IF(G79>0,H79/G79*10000,"") -> 0 | AW79: =IF(G79>0,W79/G79*10000,"") -> 0 | AX79: =IF(I79>0,K79/I79*100,"") | AY79: =IF(AQ79>=100,"ok",IF(AQ79>0,"effectif faible (<100)","aucune association")) -> aucune association
...

Sheet Cantons
A1: Indicateurs par canton
A2: Sommes calculées par SUMIFS sur l'onglet Communes ; ratios par formule.
A4: Canton | B4: Nb communes | C4: Communes sans asso. civile aidée | D4: Population | E4: Asso. civiles 2025 | F4: Adhérentes F 2025 | G4: Adhérents H 2025 | H4: Bénévoles F 2025 | I4: Salariées F 2025 | J4: Asso. <20 % F (2025) | K4: Asso. ≥60 % F (2025) | L4: Asso. civiles 2024 | M4: Adhérentes F 2024 | N4: Adhérents H 2024 | O4: Asso. scolaires 2025 | P4: Licencié·es scolaires 2025 (libellé F) | Q4: Sections scolaires 2025 | R4: Asso. civiles subventionnées 2025 | S4: Asso. scolaires subventionnées 2025 | T4: Lieux de pratique | U4: dont établissements scolaires | V4: dont piscines | W4: Manifestations 2023 | X4: Manifestations 2024 | Y4: Manifestations 2025 | Z4: Sections sportives scolaires 2026-27 | AA4: dont sections féminines | AB4: Asso. civiles 2019 | AC4: Asso. civiles 2020 | AD4: Asso. civiles 2021 | AE4: Asso. civiles 2022 | AF4: Asso. civiles 2023 | AG4: Licencié·es / adhérent·es 2019 | AH4: Licencié·es / adhérent·es 2020 | AI4: Licencié·es / adhérent·es 2021 | AJ4: Licencié·es / adhérent·es 2022 | AK4: Licencié·es / adhérent·es 2023 | AL4: Licencié·es / adhérent·es 2024 | AM4: Licencié·es / adhérent·es 2025 | AN4: Adhérent·es total 2025 | AO4: Part F 2025 | AP4: Part F 2024 | AQ4: Évolution part F (points) | AR4: Adhérentes F pour 1 000 hab. | AS4: Asso. civiles pour 10 000 hab. | AT4: Lieux pour 10 000 hab. | AU4: Bénévoles F pour 100 adhérentes | AV4: Fiabilité part F
A5: Argenteuil (1-2-3) | B5: =COUNTIF(Communes!$C$5:$C$187,A5) -> 4 | C5: =COUNTIFS(Communes!$C$5:$C$187,A5,Communes!$H$5:$H$187,0) -> 0 | D5: =SUMIFS(Communes!$G$5:$G$187,Communes!$C$5:$C$187,A5) -> 190824 | E5: =SUMIFS(Communes!$H$5:$H$187,Communes!$C$5:$C$187,A5) -> 37 | F5: =SUMIFS(Communes!$I$5:$I$187,Communes!$C$5:$C$187,A5) -> 5781 | G5: =SUMIFS(Communes!$J$5:$J$187,Communes!$C$5:$C$187,A5) -> 8420 | H5: =SUMIFS(Communes!$K$5:$K$187,Communes!$C$5:$C$187,A5) -> 1158 | I5: =SUMIFS(Communes!$L$5:$L$187,Communes!$C$5:$C$187,A5) -> 130 | J5: =SUMIFS(Communes!$M$5:$M$187,Communes!$C$5:$C$187,A5) -> 10 | K5: =SUMIFS(Communes!$N$5:$N$187,Communes!$C$5:$C$187,A5) -> 8 | L5: =SUMIFS(Communes!$O$5:$O$187,Communes!$C$5:$C$187,A5) -> 33 | M5: =SUMIFS(Communes!$P$5:$P$187,Communes!$C$5:$C$187,A5) -> 5481 | N5: =SUMIFS(Communes!$Q$5:$Q$187,Communes!$C$5:$C$187,A5) -> 6561 | O5: =SUMIFS(Communes!$R$5:$R$187,Communes!$C$5:$C$187,A5) -> 8 | P5: =SUMIFS(Communes!$S$5:$S$187,Communes!$C$5:$C$187,A5) -> 1058 | Q5: =SUMIFS(Communes!$T$5:$T$187,Communes!$C$5:$C$187,A5) -> 36 | R5: =SUMIFS(Communes!$U$5:$U$187,Communes!$C$5:$C$187,A5) -> 37 | S5: =SUMIFS(Communes!$V$5:$V$187,Communes!$C$5:$C$187,A5) -> 8 | T5: =SUMIFS(Communes!$W$5:$W$187,Communes!$C$5:$C$187,A5) -> 161 | U5: =SUMIFS(Communes!$X$5:$X$187,Communes!$C$5:$C$187,A5) -> 47 | V5: =SUMIFS(Communes!$Y$5:$Y$187,Communes!$C$5:$C$187,A5) -> 2 | W5: =SUMIFS(Communes!$Z$5:$Z$187,Communes!$C$5:$C$187,A5) -> 5 | X5: =SUMIFS(Communes!$AA$5:$AA$187,Communes!$C$5:$C$187,A5) -> 5 | Y5: =SUMIFS(Communes!$AB$5:$AB$187,Communes!$C$5:$C$187,A5) -> 4 | Z5: =SUMIFS(Communes!$AC$5:$AC$187,Communes!$C$5:$C$187,A5) -> 7 | AA5: =SUMIFS(Communes!$AD$5:$AD$187,Communes!$C$5:$C$187,A5) -> 0 | AB5: =SUMIFS(Communes!$AE$5:$AE$187,Communes!$C$5:$C$187,A5) -> 35 | AC5: =SUMIFS(Communes!$AF$5:$AF$187,Communes!$C$5:$C$187,A5) -> 40 | AD5: =SUMIFS(Communes!$AG$5:$AG$187,Communes!$C$5:$C$187,A5) -> 38 | AE5: =SUMIFS(Communes!$AH$5:$AH$187,Communes!$C$5:$C$187,A5) -> 36 | AF5: =SUMIFS(Communes!$AI$5:$AI$187,Communes!$C$5:$C$187,A5) -> 34 | AG5: =SUMIFS(Communes!$AJ$5:$AJ$187,Communes!$C$5:$C$187,A5) -> 12104 | AH5: =SUMIFS(Communes!$AK$5:$AK$187,Communes!$C$5:$C$187,A5) -> 13474 | AI5: =SUMIFS(Communes!$AL$5:$AL$187,Communes!$C$5:$C$187,A5) -> 12159 | AJ5: =SUMIFS(Communes!$AM$5:$AM$187,Communes!$C$5:$C$187,A5) -> 10325 | AK5: =SUMIFS(Communes!$AN$5:$AN$187,Communes!$C$5:$C$187,A5) -> 10715 | AL5: =SUMIFS(Communes!$AO$5:$AO$187,Communes!$C$5:$C$187,A5) -> 12042 | AM5: =SUMIFS(Communes!$AP$5:$AP$187,Communes!$C$5:$C$187,A5) -> 14201 | AN5: =F5+G5 -> 14201 | AO5: =IF(AN5>0,F5/AN5,"") -> 0.40708401 | AP5: =IF((M5+N5)>0,M5/(M5+N5),"") -> 0.45515695 | AQ5: =IF(AND(ISNUMBER(AO5),ISNUMBER(AP5)),(AO5-AP5)*100,"") -> -4.8072943 | AR5: =IF(D5>0,F5/D5*1000,"") -> 30.294931 | AS5: =IF(D5>0,E5/D5*10000,"") -> 1.9389595 | AT5: =IF(D5>0,T5/D5*10000,"") -> 8.4370939 | AU5: =IF(F5>0,H5/F5*100,"") -> 20.031136 | AV5: =IF(AN5>=100,"ok",IF(AN5>0,"effectif faible (<100)","aucune association")) -> ok
A6: Cergy (1-2) | B6: =COUNTIF(Communes!$C$5:$C$187,A6) -> 5 | C6: =COUNTIFS(Communes!$C$5:$C$187,A6,Communes!$H$5:$H$187,0) -> 0 | D6: =SUMIFS(Communes!$G$5:$G$187,Communes!$C$5:$C$187,A6) -> 127208 | E6: =SUMIFS(Communes!$H$5:$H$187,Communes!$C$5:$C$187,A6) -> 59 | F6: =SUMIFS(Communes!$I$5:$I$187,Communes!$C$5:$C$187,A6) -> 7360 | G6: =SUMIFS(Communes!$J$5:$J$187,Communes!$C$5:$C$187,A6) -> 9308 | H6: =SUMIFS(Communes!$K$5:$K$187,Communes!$C$5:$C$187,A6) -> 994 | I6: =SUMIFS(Communes!$L$5:$L$187,Communes!$C$5:$C$187,A6) -> 118 | J6: =SUMIFS(Communes!$M$5:$M$187,Communes!$C$5:$C$187,A6) -> 13 | K6: =SUMIFS(Communes!$N$5:$N$187,Communes!$C$5:$C$187,A6) -> 11 | L6: =SUMIFS(Communes!$O$5:$O$187,Communes!$C$5:$C$187,A6) -> 62 | M6: =SUMIFS(Communes!$P$5:$P$187,Communes!$C$5:$C$187,A6) -> 6792 | N6: =SUMIFS(Communes!$Q$5:$Q$187,Communes!$C$5:$C$187,A6) -> 8855 | O6: =SUMIFS(Communes!$R$5:$R$187,Communes!$C$5:$C$187,A6) -> 21 | P6: =SUMIFS(Communes!$S$5:$S$187,Communes!$C$5:$C$187,A6) -> 3659 | Q6: =SUMIFS(Communes!$T$5:$T$187,Communes!$C$5:$C$187,A6) -> 134 | R6: =SUMIFS(Communes!$U$5:$U$187,Communes!$C$5:$C$187,A6) -> 62 | S6: =SUMIFS(Communes!$V$5:$V$187,Communes!$C$5:$C$187,A6) -> 23 | T6: =SUMIFS(Communes!$W$5:$W$187,Communes!$C$5:$C$187,A6) -> 144 | U6: =SUMIFS(Communes!$X$5:$X$187,Communes!$C$5:$C$187,A6) -> 43 | V6: =SUMIFS(Communes!$Y$5:$Y$187,Communes!$C$5:$C$187,A6) -> 4 | W6: =SUMIFS(Communes!$Z$5:$Z$187,Communes!$C$5:$C$187,A6) -> 2 | X6: =SUMIFS(Communes!$AA$5:$AA$187,Communes!$C$5:$C$187,A6) -> 5 | Y6: =SUMIFS(Communes!$AB$5:$AB$187,Communes!$C$5:$C$187,A6) -> 5 | Z6: =SUMIFS(Communes!$AC$5:$AC$187,Communes!$C$5:$C$187,A6) -> 6 | AA6: =SUMIFS(Communes!$AD$5:$AD$187,Communes!$C$5:$C$187,A6) -> 0 | AB6: =SUMIFS(Communes!$AE$5:$AE$187,Communes!$C$5:$C$187,A6) -> 56 | AC6: =SUMIFS(Communes!$AF$5:$AF$187,Communes!$C$5:$C$187,A6) -> 62 | AD6: =SUMIFS(Communes!$AG$5:$AG$187,Communes!$C$5:$C$187,A6) -> 59 | AE6: =SUMIFS(Communes!$AH$5:$AH$187,Communes!$C$5:$C$187,A6) -> 60 | AF6: =SUMIFS(Communes!$AI$5:$AI$187,Communes!$C$5:$C$187,A6) -> 58 | AG6: =SUMIFS(Communes!$AJ$5:$AJ$187,Communes!$C$5:$C$187,A6) -> 10575 | AH6: =SUMIFS(Communes!$AK$5:$AK$187,Communes!$C$5:$C$187,A6) -> 11173 | AI6: =SUMIFS(Communes!$AL$5:$AL$187,Communes!$C$5:$C$187,A6) -> 10256 | AJ6: =SUMIFS(Communes!$AM$5:$AM$187,Communes!$C$5:$C$187,A6) -> 10592 | AK6: =SUMIFS(Communes!$AN$5:$AN$187,Communes!$C$5:$C$187,A6) -> 11871 | AL6: =SUMIFS(Communes!$AO$5:$AO$187,Communes!$C$5:$C$187,A6) -> 15647 | AM6: =SUMIFS(Communes!$AP$5:$AP$187,Communes!$C$5:$C$187,A6) -> 16668 | AN6: =F6+G6 -> 16668 | AO6: =IF(AN6>0,F6/AN6,"") -> 0.44156467 | AP6: =IF((M6+N6)>0,M6/(M6+N6),"") -> 0.43407682 | AQ6: =IF(AND(ISNUMBER(AO6),ISNUMBER(AP6)),(AO6-AP6)*100,"") -> 0.7487855 | AR6: =IF(D6>0,F6/D6*1000,"") -> 57.857996 | AS6: =IF(D6>0,E6/D6*10000,"") -> 4.6380731 | AT6: =IF(D6>0,T6/D6*10000,"") -> 11.320043 | AU6: =IF(F6>0,H6/F6*100,"") -> 13.505435 | AV6: =IF(AN6>=100,"ok",IF(AN6>0,"effectif faible (<100)","aucune association")) -> ok
A7: Deuil-la-Barre | B7: =COUNTIF(Communes!$C$5:$C$187,A7) -> 5 | C7: =COUNTIFS(Communes!$C$5:$C$187,A7,Communes!$H$5:$H$187,0) -> 1 | D7: =SUMIFS(Communes!$G$5:$G$187,Communes!$C$5:$C$187,A7) -> 62488 | E7: =SUMIFS(Communes!$H$5:$H$187,Communes!$C$5:$C$187,A7) -> 14 | F7: =SUMIFS(Communes!$I$5:$I$187,Communes!$C$5:$C$187,A7) -> 2199 | G7: =SUMIFS(Communes!$J$5:$J$187,Communes!$C$5:$C$187,A7) -> 3574 | H7: =SUMIFS(Communes!$K$5:$K$187,Communes!$C$5:$C$187,A7) -> 374 | I7: =SUMIFS(Communes!$L$5:$L$187,Communes!$C$5:$C$187,A7) -> 37 | J7: =SUMIFS(Communes!$M$5:$M$187,Communes!$C$5:$C$187,A7) -> 5 | K7: =SUMIFS(Communes!$N$5:$N$187,Communes!$C$5:$C$187,A7) -> 4 | L7: =SUMIFS(Communes!$O$5:$O$187,Communes!$C$5:$C$187,A7) -> 18 | M7: =SUMIFS(Communes!$P$5:$P$187,Communes!$C$5:$C$187,A7) -> 2675 | N7: =SUMIFS(Communes!$Q$5:$Q$187,Communes!$C$5:$C$187,A7) -> 4042 | O7: =SUMIFS(Communes!$R$5:$R$187,Communes!$C$5:$C$187,A7) -> 4 | P7: =SUMIFS(Communes!$S$5:$S$187,Communes!$C$5:$C$187,A7) -> 589 | Q7: =SUMIFS(Communes!$T$5:$T$187,Communes!$C$5:$C$187,A7) -> 15 | R7: =SUMIFS(Communes!$U$5:$U$187,Communes!$C$5:$C$187,A7) -> 16 | S7: =SUMIFS(Communes!$V$5:$V$187,Communes!$C$5:$C$187,A7) -> 4 | T7: =SUMIFS(Communes!$W$5:$W$187,Communes!$C$5:$C$187,A7) -> 51 | U7: =SUMIFS(Communes!$X$5:$X$187,Communes!$C$5:$C$187,A7) -> 13 | V7: =SUMIFS(Communes!$Y$5:$Y$187,Communes!$C$5:$C$187,A7) -> 0 | W7: =SUMIFS(Communes!$Z$5:$Z$187,Communes!$C$5:$C$187,A7) -> 0 | X7: =SUMIFS(Communes!$AA$5:$AA$187,Communes!$C$5:$C$187,A7) -> 1 | Y7: =SUMIFS(Communes!$AB$5:$AB$187,Communes!$C$5:$C$187,A7) -> 0 | Z7: =SUMIFS(Communes!$AC$5:$AC$187,Communes!$C$5:$C$187,A7) -> 1 | AA7: =SUMIFS(Communes!$AD$5:$AD$187,Communes!$C$5:$C$187,A7) -> 0 | AB7: =SUMIFS(Communes!$AE$5:$AE$187,Communes!$C$5:$C$187,A7) -> 22 | AC7: =SUMIFS(Communes!$AF$5:$AF$187,Communes!$C$5:$C$187,A7) -> 21 | AD7: =SUMIFS(Communes!$AG$5:$AG$187,Communes!$C$5:$C$187,A7) -> 21 | AE7: =SUMIFS(Communes!$AH$5:$AH$187,Communes!$C$5:$C$187,A7) -> 18 | AF7: =SUMIFS(Communes!$AI$5:$AI$187,Communes!$C$5:$C$187,A7) -> 17 | AG7: =SUMIFS(Communes!$AJ$5:$AJ$187,Communes!$C$5:$C$187,A7) -> 6928 | AH7: =SUMIFS(Communes!$AK$5:$AK$187,Communes!$C$5:$C$187,A7) -> 6664 | AI7: =SUMIFS(Communes!$AL$5:$AL$187,Communes!$C$5:$C$187,A7) -> 6225 | AJ7: =SUMIFS(Communes!$AM$5:$AM$187,Communes!$C$5:$C$187,A7) -> 5732 | AK7: =SUMIFS(Communes!$AN$5:$AN$187,Communes!$C$5:$C$187,A7) -> 5844 | AL7: =SUMIFS(Communes!$AO$5:$AO$187,Communes!$C$5:$C$187,A7) -> 6717 | AM7: =SUMIFS(Communes!$AP$5:$AP$187,Communes!$C$5:$C$187,A7) -> 5773 | AN7: =F7+G7 -> 5773 | AO7: =IF(AN7>0,F7/AN7,"") -> 0.38091114 | AP7: =IF((M7+N7)>0,M7/(M7+N7),"") -> 0.39824326 | AQ7: =IF(AND(ISNUMBER(AO7),ISNUMBER(AP7)),(AO7-AP7)*100,"") -> -1.7332125 | AR7: =IF(D7>0,F7/D7*1000,"") -> 35.190757 | AS7: =IF(D7>0,E7/D7*10000,"") -> 2.2404302 | AT7: =IF(D7>0,T7/D7*10000,"") -> 8.161567 | AU7: =IF(F7>0,H7/F7*100,"") -> 17.007731 | AV7: =IF(AN7>=100,"ok",IF(AN7>0,"effectif faible (<100)","aucune association")) -> ok
A8: Domont | B8: =COUNTIF(Communes!$C$5:$C$187,A8) -> 9 | C8: =COUNTIFS(Communes!$C$5:$C$187,A8,Communes!$H$5:$H$187,0) -> 2 | D8: =SUMIFS(Communes!$G$5:$G$187,Communes!$C$5:$C$187,A8) -> 64305 | E8: =SUMIFS(Communes!$H$5:$H$187,Communes!$C$5:$C$187,A8) -> 47 | F8: =SUMIFS(Communes!$I$5:$I$187,Communes!$C$5:$C$187,A8) -> 5164 | G8: =SUMIFS(Communes!$J$5:$J$187,Communes!$C$5:$C$187,A8) -> 6592 | H8: =SUMIFS(Communes!$K$5:$K$187,Communes!$C$5:$C$187,A8) -> 845 | I8: =SUMIFS(Communes!$L$5:$L$187,Communes!$C$5:$C$187,A8) -> 111 | J8: =SUMIFS(Communes!$M$5:$M$187,Communes!$C$5:$C$187,A8) -> 7 | K8: =SUMIFS(Communes!$N$5:$N$187,Communes!$C$5:$C$187,A8) -> 10 | L8: =SUMIFS(Communes!$O$5:$O$187,Communes!$C$5:$C$187,A8) -> 45 | M8: =SUMIFS(Communes!$P$5:$P$187,Communes!$C$5:$C$187,A8) -> 4839 | N8: =SUMIFS(Communes!$Q$5:$Q$187,Communes!$C$5:$C$187,A8) -> 5860 | O8: =SUMIFS(Communes!$R$5:$R$187,Communes!$C$5:$C$187,A8) -> 5 | P8: =SUMIFS(Communes!$S$5:$S$187,Communes!$C$5:$C$187,A8) -> 693 | Q8: =SUMIFS(Communes!$T$5:$T$187,Communes!$C$5:$C$187,A8) -> 20 | R8: =SUMIFS(Communes!$U$5:$U$187,Communes!$C$5:$C$187,A8) -> 45 | S8: =SUMIFS(Communes!$V$5:$V$187,Communes!$C$5:$C$187,A8) -> 5 | T8: =SUMIFS(Communes!$W$5:$W$187,Communes!$C$5:$C$187,A8) -> 74 | U8: =SUMIFS(Communes!$X$5:$X$187,Communes!$C$5:$C$187,A8) -> 15 | V8: =SUMIFS(Communes!$Y$5:$Y$187,Communes!$C$5:$C$187,A8) -> 1 | W8: =SUMIFS(Communes!$Z$5:$Z$187,Communes!$C$5:$C$187,A8) -> 6 | X8: =SUMIFS(Communes!$AA$5:$AA$187,Communes!$C$5:$C$187,A8) -> 0 | Y8: =SUMIFS(Communes!$AB$5:$AB$187,Communes!$C$5:$C$187,A8) -> 3 | Z8: =SUMIFS(Communes!$AC$5:$AC$187,Communes!$C$5:$C$187,A8) -> 1 | AA8: =SUMIFS(Communes!$AD$5:$AD$187,Communes!$C$5:$C$187,A8) -> 0 | AB8: =SUMIFS(Communes!$AE$5:$AE$187,Communes!$C$5:$C$187,A8) -> 43 | AC8: =SUMIFS(Communes!$AF$5:$AF$187,Communes!$C$5:$C$187,A8) -> 41 | AD8: =SUMIFS(Communes!$AG$5:$AG$187,Communes!$C$5:$C$187,A8) -> 46 | AE8: =SUMIFS(Communes!$AH$5:$AH$187,Communes!$C$5:$C$187,A8) -> 46 | AF8: =SUMIFS(Communes!$AI$5:$AI$187,Communes!$C$5:$C$187,A8) -> 44 | AG8: =SUMIFS(Communes!$AJ$5:$AJ$187,Communes!$C$5:$C$187,A8) -> 8032 | AH8: =SUMIFS(Communes!$AK$5:$AK$187,Communes!$C$5:$C$187,A8) -> 8520 | AI8: =SUMIFS(Communes!$AL$5:$AL$187,Communes!$C$5:$C$187,A8) -> 9187 | AJ8: =SUMIFS(Communes!$AM$5:$AM$187,Communes!$C$5:$C$187,A8) -> 9320 | AK8: =SUMIFS(Communes!$AN$5:$AN$187,Communes!$C$5:$C$187,A8) -> 9994 | AL8: =SUMIFS(Communes!$AO$5:$AO$187,Communes!$C$5:$C$187,A8) -> 10699 | AM8: =SUMIFS(Communes!$AP$5:$AP$187,Communes!$C$5:$C$187,A8) -> 11756 | AN8: =F8+G8 -> 11756 | AO8: =IF(AN8>0,F8/AN8,"") -> 0.43926506 | AP8: =IF((M8+N8)>0,M8/(M8+N8),"") -> 0.45228526 | AQ8: =IF(AND(ISNUMBER(AO8),ISNUMBER(AP8)),(AO8-AP8)*100,"") -> -1.3020204 | AR8: =IF(D8>0,F8/D8*1000,"") -> 80.304797 | AS8: =IF(D8>0,E8/D8*10000,"") -> 7.3089184 | AT8: =IF(D8>0,T8/D8*10000,"") -> 11.507659 | AU8: =IF(F8>0,H8/F8*100,"") -> 16.363284 | AV8: =IF(AN8>=100,"ok",IF(AN8>0,"effectif faible (<100)","aucune association")) -> ok
A9: Ermont | B9: =COUNTIF(Communes!$C$5:$C$187,A9) -> 2 | C9: =COUNTIFS(Communes!$C$5:$C$187,A9,Communes!$H$5:$H$187,0) -> 0 | D9: =SUMIFS(Communes!$G$5:$G$187,Communes!$C$5:$C$187,A9) -> 55700 | E9: =SUMIFS(Communes!$H$5:$H$187,Communes!$C$5:$C$187,A9) -> 22 | F9: =SUMIFS(Communes!$I$5:$I$187,Communes!$C$5:$C$187,A9) -> 3418 | G9: =SUMIFS(Communes!$J$5:$J$187,Communes!$C$5:$C$187,A9) -> 2871 | H9: =SUMIFS(Communes!$K$5:$K$187,Communes!$C$5:$C$187,A9) -> 381 | I9: =SUMIFS(Communes!$L$5:$L$187,Communes!$C$5:$C$187,A9) -> 67 | J9: =SUMIFS(Communes!$M$5:$M$187,Communes!$C$5:$C$187,A9) -> 5 | K9: =SUMIFS(Communes!$N$5:$N$187,Communes!$C$5:$C$187,A9) -> 6 | L9: =SUMIFS(Communes!$O$5:$O$187,Communes!$C$5:$C$187,A9) -> 22 | M9: =SUMIFS(Communes!$P$5:$P$187,Communes!$C$5:$C$187,A9) -> 2870 | N9: =SUMIFS(Communes!$Q$5:$Q$187,Communes!$C$5:$C$187,A9) -> 2846 | O9: =SUMIFS(Communes!$R$5:$R$187,Communes!$C$5:$C$187,A9) -> 3 | P9: =SUMIFS(Communes!$S$5:$S$187,Communes!$C$5:$C$187,A9) -> 454 | Q9: =SUMIFS(Communes!$T$5:$T$187,Communes!$C$5:$C$187,A9) -> 15 | R9: =SUMIFS(Communes!$U$5:$U$187,Communes!$C$5:$C$187,A9) -> 24 | S9: =SUMIFS(Communes!$V$5:$V$187,Communes!$C$5:$C$187,A9) -> 3 | T9: =SUMIFS(Communes!$W$5:$W$187,Communes!$C$5:$C$187,A9) -> 39 | U9: =SUMIFS(Communes!$X$5:$X$187,Communes!$C$5:$C$187,A9) -> 3 | V9: =SUMIFS(Communes!$Y$5:$Y$187,Communes!$C$5:$C$187,A9) -> 1 | W9: =SUMIFS(Communes!$Z$5:$Z$187,Communes!$C$5:$C$187,A9) -> 5 | X9: =SUMIFS(Communes!$AA$5:$AA$187,Communes!$C$5:$C$187,A9) -> 1 | Y9: =SUMIFS(Communes!$AB$5:$AB$187,Communes!$C$5:$C$187,A9) -> 5 | Z9: =SUMIFS(Communes!$AC$5:$AC$187,Communes!$C$5:$C$187,A9) -> 1 | AA9: =SUMIFS(Communes!$AD$5:$AD$187,Communes!$C$5:$C$187,A9) -> 0 | AB9: =SUMIFS(Communes!$AE$5:$AE$187,Communes!$C$5:$C$187,A9) -> 22 | AC9: =SUMIFS(Communes!$AF$5:$AF$187,Communes!$C$5:$C$187,A9) -> 22 | AD9: =SUMIFS(Communes!$AG$5:$AG$187,Communes!$C$5:$C$187,A9) -> 21 | AE9: =SUMIFS(Communes!$AH$5:$AH$187,Communes!$C$5:$C$187,A9) -> 21 | AF9: =SUMIFS(Communes!$AI$5:$AI$187,Communes!$C$5:$C$187,A9) -> 21 | AG9: =SUMIFS(Communes!$AJ$5:$AJ$187,Communes!$C$5:$C$187,A9) -> 8111 | AH9: =SUMIFS(Communes!$AK$5:$AK$187,Communes!$C$5:$C$187,A9) -> 8955 | AI9: =SUMIFS(Communes!$AL$5:$AL$187,Communes!$C$5:$C$187,A9) -> 7629 | AJ9: =SUMIFS(Communes!$AM$5:$AM$187,Communes!$C$5:$C$187,A9) -> 5004 | AK9: =SUMIFS(Communes!$AN$5:$AN$187,Communes!$C$5:$C$187,A9) -> 5010 | AL9: =SUMIFS(Communes!$AO$5:$AO$187,Communes!$C$5:$C$187,A9) -> 5716 | AM9: =SUMIFS(Communes!$AP$5:$AP$187,Communes!$C$5:$C$187,A9) -> 6289 | AN9: =F9+G9 -> 6289 | AO9: =IF(AN9>0,F9/AN9,"") -> 0.54348863 | AP9: =IF((M9+N9)>0,M9/(M9+N9),"") -> 0.50209937 | AQ9: =IF(AND(ISNUMBER(AO9),ISNUMBER(AP9)),(AO9-AP9)*100,"") -> 4.1389261 | AR9: =IF(D9>0,F9/D9*1000,"") -> 61.364452 | AS9: =IF(D9>0,E9/D9*10000,"") -> 3.9497307 | AT9: =IF(D9>0,T9/D9*10000,"") -> 7.0017953 | AU9: =IF(F9>0,H9/F9*100,"") -> 11.14687 | AV9: =IF(AN9>=100,"ok",IF(AN9>0,"effectif faible (<100)","aucune association")) -> ok
